05-27 16:03:23 jdbc[6]: exception
org.h2.jdbc.JdbcSQLException: テーブル "PLAY_EVOLUTIONS" が見つかりません
Table "PLAY_EVOLUTIONS" not found; SQL statement:
select id, hash, apply_script, revert_script, state, last_problem from play_evolutions where state like 'applying_%' [42102-175]
05-28 11:11:40 jdbc[28]: exception
org.h2.jdbc.JdbcSQLException: SQLステートメントに文法エラーがあります "SELECT T0.EMP_ID C0, T0.EMP_NAME C1, T0.PASSWORD C2, T0.JOB_ID C3, T0.DEPT_ID C4 FROM EMPLOYEES T0 WHERE STRING.VALUEOF([*]T0.EMP_ID) = ?  "
Syntax error in SQL statement "SELECT T0.EMP_ID C0, T0.EMP_NAME C1, T0.PASSWORD C2, T0.JOB_ID C3, T0.DEPT_ID C4 FROM EMPLOYEES T0 WHERE STRING.VALUEOF([*]T0.EMP_ID) = ?  "; SQL statement:
select t0.emp_id c0, t0.emp_name c1, t0.password c2, t0.job_id c3, t0.dept_id c4 from employees t0 where String.valueOf(t0.emp_id) = ?  [42000-175]
05-28 11:13:14 jdbc[35]: exception
org.h2.jdbc.JdbcSQLException: SQLステートメントに文法エラーがあります "SELECT T0.EMP_ID C0, T0.EMP_NAME C1, T0.PASSWORD C2, T0.JOB_ID C3, T0.DEPT_ID C4 FROM EMPLOYEES T0 WHERE STRING.VALUEOF([*]T0.EMP_ID) = ?  "
Syntax error in SQL statement "SELECT T0.EMP_ID C0, T0.EMP_NAME C1, T0.PASSWORD C2, T0.JOB_ID C3, T0.DEPT_ID C4 FROM EMPLOYEES T0 WHERE STRING.VALUEOF([*]T0.EMP_ID) = ?  "; SQL statement:
select t0.emp_id c0, t0.emp_name c1, t0.password c2, t0.job_id c3, t0.dept_id c4 from employees t0 where String.valueOf(t0.emp_id) = ?  [42000-175]
05-28 11:16:13 jdbc[42]: exception
org.h2.jdbc.JdbcSQLException: SQLステートメントに文法エラーがあります "SELECT T0.EMP_ID C0, T0.EMP_NAME C1, T0.PASSWORD C2, T0.JOB_ID C3, T0.DEPT_ID C4 FROM EMPLOYEES T0 WHERE STRING.VALUEOF([*]T0.EMP_ID) = ?  "
Syntax error in SQL statement "SELECT T0.EMP_ID C0, T0.EMP_NAME C1, T0.PASSWORD C2, T0.JOB_ID C3, T0.DEPT_ID C4 FROM EMPLOYEES T0 WHERE STRING.VALUEOF([*]T0.EMP_ID) = ?  "; SQL statement:
select t0.emp_id c0, t0.emp_name c1, t0.password c2, t0.job_id c3, t0.dept_id c4 from employees t0 where String.valueOf(t0.emp_id) = ?  [42000-175]
05-28 11:49:40 jdbc[80]: exception
org.h2.jdbc.JdbcSQLException: データ変換中にエラーが発生しました "ctg"
Data conversion error converting "ctg"; SQL statement:
select t0.category_id c0, t0.category_name c1 from categories t0 where t0.category_id = ?  [22018-175]
05-28 11:50:19 jdbc[87]: exception
org.h2.jdbc.JdbcSQLException: データ変換中にエラーが発生しました "num"
Data conversion error converting "num"; SQL statement:
select t0.category_id c0, t0.category_name c1 from categories t0 where t0.category_id = ?  [22018-175]
05-28 11:55:44 jdbc[94]: exception
org.h2.jdbc.JdbcSQLException: データ変換中にエラーが発生しました "num"
Data conversion error converting "num"; SQL statement:
select t0.category_id c0, t0.category_name c1 from categories t0 where t0.category_id = ?  [22018-175]
05-28 13:24:18 jdbc[159]: exception
org.h2.jdbc.JdbcSQLException: "TIMESTAMP" 定数 "20150527" を解析できません
Cannot parse "TIMESTAMP" constant "20150527"; SQL statement:
INSERT INTO "PUBLIC"."THANKS"("TNKCARD_ID","TNK_ID","HELP_CONTENTS","TNK_CONTENTS","CATEGORY_ID","YWK_ID","TNK_DATE","TNK_POINT")VALUES(?,?,?,?,?,?,?,?) -- (?1, ?2, ?3, ?4, ?5, ?6, ?7, ?8) [22007-175]
	at org.h2.message.DbException.getJdbcSQLException(DbException.java:332)
	at org.h2.message.DbException.get(DbException.java:161)
	at org.h2.value.ValueTimestamp.parse(ValueTimestamp.java:87)
	at org.h2.value.Value.convertTo(Value.java:843)
	at org.h2.table.Column.convert(Column.java:145)
	at org.h2.command.dml.Insert.insertRows(Insert.java:144)
	at org.h2.command.dml.Insert.update(Insert.java:115)
	at org.h2.command.CommandContainer.update(CommandContainer.java:79)
	at org.h2.command.Command.executeUpdate(Command.java:253)
	at org.h2.jdbc.JdbcPreparedStatement.executeUpdateInternal(JdbcPreparedStatement.java:154)
	at org.h2.jdbc.JdbcPreparedStatement.executeUpdate(JdbcPreparedStatement.java:140)
	at org.h2.result.UpdatableRow.insertRow(UpdatableRow.java:320)
	at org.h2.jdbc.JdbcResultSet.insertRow(JdbcResultSet.java:2893)
	at org.h2.server.web.WebApp.editResult(WebApp.java:1031)
	at org.h2.server.web.WebApp.process(WebApp.java:225)
	at org.h2.server.web.WebApp.processRequest(WebApp.java:168)
	at org.h2.server.web.WebThread.process(WebThread.java:138)
	at org.h2.server.web.WebThread.run(WebThread.java:94)
	at java.lang.Thread.run(Unknown Source)
Caused by: java.lang.IllegalArgumentException: 20150527
	at org.h2.util.DateTimeUtils.parseDateValue(DateTimeUtils.java:270)
	at org.h2.value.ValueTimestamp.parseTry(ValueTimestamp.java:105)
	at org.h2.value.ValueTimestamp.parse(ValueTimestamp.java:85)
	... 16 more
05-28 13:24:18 jdbc[159]: exception
org.h2.jdbc.JdbcSQLException: "TIMESTAMP" 定数 "20150527" を解析できません
Cannot parse "TIMESTAMP" constant "20150527"; SQL statement:
INSERT INTO "PUBLIC"."THANKS"("TNKCARD_ID","TNK_ID","HELP_CONTENTS","TNK_CONTENTS","CATEGORY_ID","YWK_ID","TNK_DATE","TNK_POINT")VALUES(?,?,?,?,?,?,?,?) -- (?1, ?2, ?3, ?4, ?5, ?6, ?7, ?8) [22007-175]
	at org.h2.message.DbException.getJdbcSQLException(DbException.java:332)
	at org.h2.message.DbException.get(DbException.java:161)
	at org.h2.value.ValueTimestamp.parse(ValueTimestamp.java:87)
	at org.h2.value.Value.convertTo(Value.java:843)
	at org.h2.table.Column.convert(Column.java:145)
	at org.h2.command.dml.Insert.insertRows(Insert.java:144)
	at org.h2.command.dml.Insert.update(Insert.java:115)
	at org.h2.command.CommandContainer.update(CommandContainer.java:79)
	at org.h2.command.Command.executeUpdate(Command.java:253)
	at org.h2.jdbc.JdbcPreparedStatement.executeUpdateInternal(JdbcPreparedStatement.java:154)
	at org.h2.jdbc.JdbcPreparedStatement.executeUpdate(JdbcPreparedStatement.java:140)
	at org.h2.result.UpdatableRow.insertRow(UpdatableRow.java:320)
	at org.h2.jdbc.JdbcResultSet.insertRow(JdbcResultSet.java:2893)
	at org.h2.server.web.WebApp.editResult(WebApp.java:1031)
	at org.h2.server.web.WebApp.process(WebApp.java:225)
	at org.h2.server.web.WebApp.processRequest(WebApp.java:168)
	at org.h2.server.web.WebThread.process(WebThread.java:138)
	at org.h2.server.web.WebThread.run(WebThread.java:94)
	at java.lang.Thread.run(Unknown Source)
Caused by: java.lang.IllegalArgumentException: 20150527
	at org.h2.util.DateTimeUtils.parseDateValue(DateTimeUtils.java:270)
	at org.h2.value.ValueTimestamp.parseTry(ValueTimestamp.java:105)
	at org.h2.value.ValueTimestamp.parse(ValueTimestamp.java:85)
	... 16 more
05-28 14:07:06 jdbc[6]: exception
org.h2.jdbc.JdbcSQLException: データ変換中にエラーが発生しました "兼島　大佑"
Data conversion error converting "兼島　大佑"; SQL statement:
select t0.emp_id c0, t0.emp_name c1, t0.password c2, t0.job_id c3, t0.dept_id c4 from employees t0 where t0.emp_name = ?  and t0.dept_id = ?  [22018-175]
05-28 14:07:47 jdbc[6]: exception
org.h2.jdbc.JdbcSQLException: データ変換中にエラーが発生しました "兼島　大佑"
Data conversion error converting "兼島　大佑"; SQL statement:
select t0.emp_id c0, t0.emp_name c1, t0.password c2, t0.job_id c3, t0.dept_id c4 from employees t0 where t0.emp_name = ?  and t0.dept_id = ?  [22018-175]
05-28 14:50:20 jdbc[3]: exception
org.h2.jdbc.JdbcSQLException: SQLステートメントに文法エラーがあります "DELETE *[*] THANKS "; 期待されるステートメント "identifier"
Syntax error in SQL statement "DELETE *[*] THANKS "; expected "identifier"; SQL statement:
delete * thanks [42001-175]
05-28 15:28:32 jdbc[31]: exception
org.h2.jdbc.JdbcSQLException: データ変換中にエラーが発生しました "兼島　大佑"
Data conversion error converting "兼島　大佑"; SQL statement:
select t0.emp_id c0, t0.emp_name c1, t0.password c2, t0.job_id c3, t0.dept_id c4 from employees t0 where t0.emp_id = ?  and t0.dept_id = ?  [22018-175]
05-29 10:15:27 jdbc[8]: exception
org.h2.jdbc.JdbcSQLException: データ変換中にエラーが発生しました "'' (EMPLOYEES: JOB_ID INTEGER)"
Data conversion error converting "'' (EMPLOYEES: JOB_ID INTEGER)"; SQL statement:
INSERT INTO "PUBLIC"."EMPLOYEES"("EMP_ID","EMP_NAME","DEPT_ID","PASSWORD","JOB_ID")VALUES(?,?,?,?,?) -- (?1, ?2, ?3, ?4, ?5) [22018-175]
05-29 10:15:27 jdbc[8]: exception
org.h2.jdbc.JdbcSQLException: データ変換中にエラーが発生しました "'' (EMPLOYEES: JOB_ID INTEGER)"
Data conversion error converting "'' (EMPLOYEES: JOB_ID INTEGER)"; SQL statement:
INSERT INTO "PUBLIC"."EMPLOYEES"("EMP_ID","EMP_NAME","DEPT_ID","PASSWORD","JOB_ID")VALUES(?,?,?,?,?) -- (?1, ?2, ?3, ?4, ?5) [22018-175]
05-29 10:15:50 jdbc[8]: exception
org.h2.jdbc.JdbcSQLException: データ変換中にエラーが発生しました "'' (EMPLOYEES: DEPT_ID INTEGER)"
Data conversion error converting "'' (EMPLOYEES: DEPT_ID INTEGER)"; SQL statement:
INSERT INTO "PUBLIC"."EMPLOYEES"("EMP_ID","EMP_NAME","DEPT_ID","PASSWORD","JOB_ID")VALUES(?,?,?,?,?) -- (?1, ?2, ?3, ?4, ?5) [22018-175]
05-29 10:15:50 jdbc[8]: exception
org.h2.jdbc.JdbcSQLException: データ変換中にエラーが発生しました "'' (EMPLOYEES: DEPT_ID INTEGER)"
Data conversion error converting "'' (EMPLOYEES: DEPT_ID INTEGER)"; SQL statement:
INSERT INTO "PUBLIC"."EMPLOYEES"("EMP_ID","EMP_NAME","DEPT_ID","PASSWORD","JOB_ID")VALUES(?,?,?,?,?) -- (?1, ?2, ?3, ?4, ?5) [22018-175]
05-29 10:21:23 jdbc[8]: exception
org.h2.jdbc.JdbcSQLException: データ変換中にエラーが発生しました "'' (THANKS: CATEGORY_ID INTEGER)"
Data conversion error converting "'' (THANKS: CATEGORY_ID INTEGER)"; SQL statement:
INSERT INTO "PUBLIC"."THANKS"("TNKCARD_ID","TNK_ID","HELP_CONTENTS","TNK_CONTENTS","CATEGORY_ID","YWK_ID","TNK_DATE","TNK_POINT")VALUES(?,?,?,?,?,?,?,?) -- (?1, ?2, ?3, ?4, ?5, ?6, ?7, ?8) [22018-175]
05-29 10:21:23 jdbc[8]: exception
org.h2.jdbc.JdbcSQLException: データ変換中にエラーが発生しました "'' (THANKS: CATEGORY_ID INTEGER)"
Data conversion error converting "'' (THANKS: CATEGORY_ID INTEGER)"; SQL statement:
INSERT INTO "PUBLIC"."THANKS"("TNKCARD_ID","TNK_ID","HELP_CONTENTS","TNK_CONTENTS","CATEGORY_ID","YWK_ID","TNK_DATE","TNK_POINT")VALUES(?,?,?,?,?,?,?,?) -- (?1, ?2, ?3, ?4, ?5, ?6, ?7, ?8) [22018-175]
05-29 10:22:49 jdbc[8]: exception
org.h2.jdbc.JdbcSQLException: "TIMESTAMP" 定数 "2015/05/01" を解析できません
Cannot parse "TIMESTAMP" constant "2015/05/01"; SQL statement:
INSERT INTO "PUBLIC"."THANKS"("TNKCARD_ID","TNK_ID","HELP_CONTENTS","TNK_CONTENTS","CATEGORY_ID","YWK_ID","TNK_DATE","TNK_POINT")VALUES(?,?,?,?,?,?,?,?) -- (?1, ?2, ?3, ?4, ?5, ?6, ?7, ?8) [22007-175]
	at org.h2.message.DbException.getJdbcSQLException(DbException.java:332)
	at org.h2.message.DbException.get(DbException.java:161)
	at org.h2.value.ValueTimestamp.parse(ValueTimestamp.java:87)
	at org.h2.value.Value.convertTo(Value.java:843)
	at org.h2.table.Column.convert(Column.java:145)
	at org.h2.command.dml.Insert.insertRows(Insert.java:144)
	at org.h2.command.dml.Insert.update(Insert.java:115)
	at org.h2.command.CommandContainer.update(CommandContainer.java:79)
	at org.h2.command.Command.executeUpdate(Command.java:253)
	at org.h2.jdbc.JdbcPreparedStatement.executeUpdateInternal(JdbcPreparedStatement.java:154)
	at org.h2.jdbc.JdbcPreparedStatement.executeUpdate(JdbcPreparedStatement.java:140)
	at org.h2.result.UpdatableRow.insertRow(UpdatableRow.java:320)
	at org.h2.jdbc.JdbcResultSet.insertRow(JdbcResultSet.java:2893)
	at org.h2.server.web.WebApp.editResult(WebApp.java:1031)
	at org.h2.server.web.WebApp.process(WebApp.java:225)
	at org.h2.server.web.WebApp.processRequest(WebApp.java:168)
	at org.h2.server.web.WebThread.process(WebThread.java:138)
	at org.h2.server.web.WebThread.run(WebThread.java:94)
	at java.lang.Thread.run(Unknown Source)
Caused by: java.lang.IllegalArgumentException: 2015/05/01
	at org.h2.util.DateTimeUtils.parseDateValue(DateTimeUtils.java:270)
	at org.h2.value.ValueTimestamp.parseTry(ValueTimestamp.java:105)
	at org.h2.value.ValueTimestamp.parse(ValueTimestamp.java:85)
	... 16 more
05-29 10:22:49 jdbc[8]: exception
org.h2.jdbc.JdbcSQLException: "TIMESTAMP" 定数 "2015/05/01" を解析できません
Cannot parse "TIMESTAMP" constant "2015/05/01"; SQL statement:
INSERT INTO "PUBLIC"."THANKS"("TNKCARD_ID","TNK_ID","HELP_CONTENTS","TNK_CONTENTS","CATEGORY_ID","YWK_ID","TNK_DATE","TNK_POINT")VALUES(?,?,?,?,?,?,?,?) -- (?1, ?2, ?3, ?4, ?5, ?6, ?7, ?8) [22007-175]
	at org.h2.message.DbException.getJdbcSQLException(DbException.java:332)
	at org.h2.message.DbException.get(DbException.java:161)
	at org.h2.value.ValueTimestamp.parse(ValueTimestamp.java:87)
	at org.h2.value.Value.convertTo(Value.java:843)
	at org.h2.table.Column.convert(Column.java:145)
	at org.h2.command.dml.Insert.insertRows(Insert.java:144)
	at org.h2.command.dml.Insert.update(Insert.java:115)
	at org.h2.command.CommandContainer.update(CommandContainer.java:79)
	at org.h2.command.Command.executeUpdate(Command.java:253)
	at org.h2.jdbc.JdbcPreparedStatement.executeUpdateInternal(JdbcPreparedStatement.java:154)
	at org.h2.jdbc.JdbcPreparedStatement.executeUpdate(JdbcPreparedStatement.java:140)
	at org.h2.result.UpdatableRow.insertRow(UpdatableRow.java:320)
	at org.h2.jdbc.JdbcResultSet.insertRow(JdbcResultSet.java:2893)
	at org.h2.server.web.WebApp.editResult(WebApp.java:1031)
	at org.h2.server.web.WebApp.process(WebApp.java:225)
	at org.h2.server.web.WebApp.processRequest(WebApp.java:168)
	at org.h2.server.web.WebThread.process(WebThread.java:138)
	at org.h2.server.web.WebThread.run(WebThread.java:94)
	at java.lang.Thread.run(Unknown Source)
Caused by: java.lang.IllegalArgumentException: 2015/05/01
	at org.h2.util.DateTimeUtils.parseDateValue(DateTimeUtils.java:270)
	at org.h2.value.ValueTimestamp.parseTry(ValueTimestamp.java:105)
	at org.h2.value.ValueTimestamp.parse(ValueTimestamp.java:85)
	... 16 more
05-29 10:29:33 jdbc[21]: null
org.h2.message.DbException: アプリケーションにより閉じられていない接続がガベージコレクトされました
The connection was not closed by the application and is garbage collected [90018-175]
	at org.h2.message.DbException.get(DbException.java:172)
	at org.h2.message.DbException.get(DbException.java:149)
	at org.h2.message.DbException.get(DbException.java:138)
	at org.h2.jdbc.JdbcConnection.closeOld(JdbcConnection.java:171)
	at org.h2.jdbc.JdbcConnection.<init>(JdbcConnection.java:116)
	at org.h2.jdbc.JdbcConnection.<init>(JdbcConnection.java:90)
	at org.h2.Driver.connect(Driver.java:73)
	at java.sql.DriverManager.getConnection(Unknown Source)
	at java.sql.DriverManager.getConnection(Unknown Source)
	at com.jolbox.bonecp.BoneCP.obtainRawInternalConnection(BoneCP.java:351)
	at com.jolbox.bonecp.BoneCP.<init>(BoneCP.java:416)
	at com.jolbox.bonecp.BoneCPDataSource.getConnection(BoneCPDataSource.java:120)
	at play.api.db.BoneCPPlugin$$anonfun$onStart$1.apply(DB.scala:240)
	at play.api.db.BoneCPPlugin$$anonfun$onStart$1.apply(DB.scala:238)
	at scala.collection.immutable.List.map(List.scala:273)
	at play.api.db.BoneCPPlugin.onStart(DB.scala:238)
	at play.api.Play$$anonfun$start$1$$anonfun$apply$mcV$sp$1.apply(Play.scala:91)
	at play.api.Play$$anonfun$start$1$$anonfun$apply$mcV$sp$1.apply(Play.scala:91)
	at scala.collection.immutable.List.foreach(List.scala:381)
	at play.api.Play$$anonfun$start$1.apply$mcV$sp(Play.scala:91)
	at play.api.Play$$anonfun$start$1.apply(Play.scala:91)
	at play.api.Play$$anonfun$start$1.apply(Play.scala:91)
	at play.utils.Threads$.withContextClassLoader(Threads.scala:21)
	at play.api.Play$.start(Play.scala:90)
	at play.core.ReloadableApplication$$anonfun$get$1$$anonfun$apply$1$$anonfun$1.apply(ApplicationProvider.scala:157)
	at play.core.ReloadableApplication$$anonfun$get$1$$anonfun$apply$1$$anonfun$1.apply(ApplicationProvider.scala:130)
	at scala.Option.map(Option.scala:146)
	at play.core.ReloadableApplication$$anonfun$get$1$$anonfun$apply$1.apply(ApplicationProvider.scala:130)
	at play.core.ReloadableApplication$$anonfun$get$1$$anonfun$apply$1.apply(ApplicationProvider.scala:128)
	at scala.util.Success.flatMap(Try.scala:230)
	at play.core.ReloadableApplication$$anonfun$get$1.apply(ApplicationProvider.scala:128)
	at play.core.ReloadableApplication$$anonfun$get$1.apply(ApplicationProvider.scala:120)
	at scala.concurrent.impl.Future$PromiseCompletingRunnable.liftedTree1$1(Future.scala:24)
	at scala.concurrent.impl.Future$PromiseCompletingRunnable.run(Future.scala:24)
	at scala.concurrent.forkjoin.ForkJoinTask$AdaptedRunnableAction.exec(ForkJoinTask.java:1361)
	at scala.concurrent.forkjoin.ForkJoinTask.doExec(ForkJoinTask.java:260)
	at scala.concurrent.forkjoin.ForkJoinPool$WorkQueue.runTask(ForkJoinPool.java:1339)
	at scala.concurrent.forkjoin.ForkJoinPool.runWorker(ForkJoinPool.java:1979)
	at scala.concurrent.forkjoin.ForkJoinWorkerThread.run(ForkJoinWorkerThread.java:107)
Caused by: org.h2.jdbc.JdbcSQLException: アプリケーションにより閉じられていない接続がガベージコレクトされました
The connection was not closed by the application and is garbage collected [90018-175]
	at org.h2.message.DbException.getJdbcSQLException(DbException.java:332)
	... 39 more
